{
 "cells": [
  {
   "cell_type": "code",
   "execution_count": 6,
   "id": "47539555",
   "metadata": {},
   "outputs": [],
   "source": [
    "import tensorflow as tf\n",
    "from tensorflow.keras.applications import VGG16, VGG19\n",
    "from tensorflow.keras.applications import ResNet50\n",
    "from tensorflow.keras.preprocessing.image import ImageDataGenerator\n",
    "\n",
    "from tensorflow.keras.layers import GlobalMaxPooling2D, Dense, Dropout\n",
    "from tensorflow.keras.models import Model\n",
    "from tensorflow.keras.optimizers import Adamax\n",
    "import matplotlib.pyplot as plt\n",
    "import pandas as pd\n"
   ]
  },
  {
   "cell_type": "code",
   "execution_count": 7,
   "id": "ad71eaa5",
   "metadata": {},
   "outputs": [
    {
     "name": "stdout",
     "output_type": "stream",
     "text": [
      "Requirement already satisfied: tf-nightly in /Users/challa/opt/anaconda3/lib/python3.9/site-packages (2.17.0.dev20240518)\n",
      "Requirement already satisfied: tensorflow-io-gcs-filesystem>=0.23.1 in /Users/challa/opt/anaconda3/lib/python3.9/site-packages (from tf-nightly) (0.37.0)\n",
      "Requirement already satisfied: flatbuffers>=24.3.25 in /Users/challa/opt/anaconda3/lib/python3.9/site-packages (from tf-nightly) (24.3.25)\n",
      "Requirement already satisfied: termcolor>=1.1.0 in /Users/challa/opt/anaconda3/lib/python3.9/site-packages (from tf-nightly) (2.4.0)\n",
      "Requirement already satisfied: packaging in /Users/challa/opt/anaconda3/lib/python3.9/site-packages (from tf-nightly) (21.0)\n",
      "Requirement already satisfied: astunparse>=1.6.0 in /Users/challa/opt/anaconda3/lib/python3.9/site-packages (from tf-nightly) (1.6.3)\n",
      "Requirement already satisfied: h5py>=3.10.0 in /Users/challa/opt/anaconda3/lib/python3.9/site-packages (from tf-nightly) (3.11.0)\n",
      "Requirement already satisfied: gast!=0.5.0,!=0.5.1,!=0.5.2,>=0.2.1 in /Users/challa/opt/anaconda3/lib/python3.9/site-packages (from tf-nightly) (0.5.4)\n",
      "Requirement already satisfied: protobuf!=4.21.0,!=4.21.1,!=4.21.2,!=4.21.3,!=4.21.4,!=4.21.5,<5.0.0dev,>=3.20.3 in /Users/challa/opt/anaconda3/lib/python3.9/site-packages (from tf-nightly) (4.25.3)\n",
      "Requirement already satisfied: tb-nightly~=2.17.0.a in /Users/challa/opt/anaconda3/lib/python3.9/site-packages (from tf-nightly) (2.17.0a20240518)\n",
      "Requirement already satisfied: requests<3,>=2.21.0 in /Users/challa/opt/anaconda3/lib/python3.9/site-packages (from tf-nightly) (2.26.0)\n",
      "Requirement already satisfied: libclang>=13.0.0 in /Users/challa/opt/anaconda3/lib/python3.9/site-packages (from tf-nightly) (18.1.1)\n",
      "Requirement already satisfied: six>=1.12.0 in /Users/challa/opt/anaconda3/lib/python3.9/site-packages (from tf-nightly) (1.16.0)\n",
      "Requirement already satisfied: opt-einsum>=2.3.2 in /Users/challa/opt/anaconda3/lib/python3.9/site-packages (from tf-nightly) (3.3.0)\n",
      "Requirement already satisfied: wrapt>=1.11.0 in /Users/challa/opt/anaconda3/lib/python3.9/site-packages (from tf-nightly) (1.12.1)\n",
      "Requirement already satisfied: google-pasta>=0.1.1 in /Users/challa/opt/anaconda3/lib/python3.9/site-packages (from tf-nightly) (0.2.0)\n",
      "Requirement already satisfied: grpcio<2.0,>=1.24.3 in /Users/challa/opt/anaconda3/lib/python3.9/site-packages (from tf-nightly) (1.63.0)\n",
      "Requirement already satisfied: numpy<2.0.0,>=1.23.5 in /Users/challa/opt/anaconda3/lib/python3.9/site-packages (from tf-nightly) (1.26.4)\n",
      "Requirement already satisfied: keras-nightly>=3.2.0.dev in /Users/challa/opt/anaconda3/lib/python3.9/site-packages (from tf-nightly) (3.3.3.dev2024051903)\n",
      "Requirement already satisfied: absl-py>=1.0.0 in /Users/challa/opt/anaconda3/lib/python3.9/site-packages (from tf-nightly) (2.1.0)\n",
      "Requirement already satisfied: ml-dtypes~=0.3.1 in /Users/challa/opt/anaconda3/lib/python3.9/site-packages (from tf-nightly) (0.3.2)\n",
      "Requirement already satisfied: typing-extensions>=3.6.6 in /Users/challa/opt/anaconda3/lib/python3.9/site-packages (from tf-nightly) (4.7.1)\n",
      "Requirement already satisfied: setuptools in /Users/challa/opt/anaconda3/lib/python3.9/site-packages (from tf-nightly) (68.1.2)\n",
      "Requirement already satisfied: wheel<1.0,>=0.23.0 in /Users/challa/opt/anaconda3/lib/python3.9/site-packages (from astunparse>=1.6.0->tf-nightly) (0.37.0)\n",
      "Requirement already satisfied: namex in /Users/challa/opt/anaconda3/lib/python3.9/site-packages (from keras-nightly>=3.2.0.dev->tf-nightly) (0.0.8)\n",
      "Requirement already satisfied: optree in /Users/challa/opt/anaconda3/lib/python3.9/site-packages (from keras-nightly>=3.2.0.dev->tf-nightly) (0.11.0)\n",
      "Requirement already satisfied: rich in /Users/challa/opt/anaconda3/lib/python3.9/site-packages (from keras-nightly>=3.2.0.dev->tf-nightly) (13.5.3)\n",
      "Requirement already satisfied: idna<4,>=2.5 in /Users/challa/opt/anaconda3/lib/python3.9/site-packages (from requests<3,>=2.21.0->tf-nightly) (3.2)\n",
      "Requirement already satisfied: urllib3<1.27,>=1.21.1 in /Users/challa/opt/anaconda3/lib/python3.9/site-packages (from requests<3,>=2.21.0->tf-nightly) (1.26.7)\n",
      "Requirement already satisfied: certifi>=2017.4.17 in /Users/challa/opt/anaconda3/lib/python3.9/site-packages (from requests<3,>=2.21.0->tf-nightly) (2021.10.8)\n",
      "Requirement already satisfied: charset-normalizer~=2.0.0 in /Users/challa/opt/anaconda3/lib/python3.9/site-packages (from requests<3,>=2.21.0->tf-nightly) (2.0.4)\n",
      "Requirement already satisfied: tensorboard-data-server<0.8.0,>=0.7.0 in /Users/challa/opt/anaconda3/lib/python3.9/site-packages (from tb-nightly~=2.17.0.a->tf-nightly) (0.7.2)\n",
      "Requirement already satisfied: markdown>=2.6.8 in /Users/challa/opt/anaconda3/lib/python3.9/site-packages (from tb-nightly~=2.17.0.a->tf-nightly) (3.6)\n",
      "Requirement already satisfied: werkzeug>=1.0.1 in /Users/challa/opt/anaconda3/lib/python3.9/site-packages (from tb-nightly~=2.17.0.a->tf-nightly) (2.0.2)\n",
      "Requirement already satisfied: importlib-metadata>=4.4 in /Users/challa/opt/anaconda3/lib/python3.9/site-packages (from markdown>=2.6.8->tb-nightly~=2.17.0.a->tf-nightly) (4.8.1)\n",
      "Requirement already satisfied: zipp>=0.5 in /Users/challa/opt/anaconda3/lib/python3.9/site-packages (from importlib-metadata>=4.4->markdown>=2.6.8->tb-nightly~=2.17.0.a->tf-nightly) (3.6.0)\n",
      "Requirement already satisfied: pyparsing>=2.0.2 in /Users/challa/opt/anaconda3/lib/python3.9/site-packages (from packaging->tf-nightly) (3.0.4)\n",
      "Requirement already satisfied: markdown-it-py>=2.2.0 in /Users/challa/opt/anaconda3/lib/python3.9/site-packages (from rich->keras-nightly>=3.2.0.dev->tf-nightly) (3.0.0)\n",
      "Requirement already satisfied: pygments<3.0.0,>=2.13.0 in /Users/challa/opt/anaconda3/lib/python3.9/site-packages (from rich->keras-nightly>=3.2.0.dev->tf-nightly) (2.16.1)\n",
      "Requirement already satisfied: mdurl~=0.1 in /Users/challa/opt/anaconda3/lib/python3.9/site-packages (from markdown-it-py>=2.2.0->rich->keras-nightly>=3.2.0.dev->tf-nightly) (0.1.2)\n"
     ]
    }
   ],
   "source": [
    "tf.__version__\n",
    "!pip install tf-nightly\n"
   ]
  },
  {
   "cell_type": "code",
   "execution_count": 8,
   "id": "916a80c7",
   "metadata": {},
   "outputs": [],
   "source": [
    "train_dir = './archive/train'\n",
    "test_dir = './archive/test'\n",
    "val_dir = './archive/valid'"
   ]
  },
  {
   "cell_type": "code",
   "execution_count": 9,
   "id": "4a5d67e9",
   "metadata": {},
   "outputs": [],
   "source": [
    "img_height, img_width = 227, 227\n",
    "batch_size = 64\n",
    "\n",
    "train_datagen = ImageDataGenerator(\n",
    "    rescale=1./255,\n",
    "    rotation_range=40,\n",
    "    width_shift_range=0.2,\n",
    "    height_shift_range=0.2,\n",
    "    shear_range=0.2,\n",
    "    zoom_range=0.2,\n",
    "    horizontal_flip=True,\n",
    "    fill_mode='nearest'\n",
    ")"
   ]
  },
  {
   "cell_type": "code",
   "execution_count": 10,
   "id": "5d3ca120",
   "metadata": {},
   "outputs": [
    {
     "name": "stdout",
     "output_type": "stream",
     "text": [
      "Found 2536 images belonging to 2 classes.\n"
     ]
    }
   ],
   "source": [
    "test_datagen = ImageDataGenerator(rescale=1./255)\n",
    "\n",
    "train_generator = train_datagen.flow_from_directory(\n",
    "    train_dir,\n",
    "    target_size=(img_height, img_width),\n",
    "    batch_size=batch_size,\n",
    "    class_mode='binary'\n",
    ")"
   ]
  },
  {
   "cell_type": "code",
   "execution_count": 11,
   "id": "92da7e1f",
   "metadata": {},
   "outputs": [
    {
     "name": "stdout",
     "output_type": "stream",
     "text": [
      "Found 100 images belonging to 2 classes.\n",
      "Found 300 images belonging to 2 classes.\n"
     ]
    }
   ],
   "source": [
    "validation_generator = test_datagen.flow_from_directory(\n",
    "    val_dir,\n",
    "    target_size=(img_height, img_width),\n",
    "    batch_size=batch_size,\n",
    "    class_mode='binary'\n",
    ")\n",
    "\n",
    "test_generator = test_datagen.flow_from_directory(\n",
    "    test_dir,\n",
    "    target_size=(img_height, img_width),\n",
    "    batch_size=batch_size,\n",
    "    class_mode='binary'\n",
    ")\n"
   ]
  },
  {
   "cell_type": "code",
   "execution_count": 12,
   "id": "46c27ceb",
   "metadata": {},
   "outputs": [],
   "source": [
    "def create_model(base_model):\n",
    "    x = base_model.output\n",
    "    x = GlobalMaxPooling2D()(x)\n",
    "    x = Dense(512, activation='relu')(x)\n",
    "    x = Dropout(0.5)(x)\n",
    "    x = Dense(256, activation='relu')(x)\n",
    "    x = Dropout(0.5)(x)\n",
    "    x = Dense(128, activation='relu')(x)\n",
    "    x = Dropout(0.5)(x)\n",
    "    x = Dense(64, activation='relu')(x)\n",
    "    x = Dropout(0.5)(x)\n",
    "    x = Dense(32, activation='relu')(x)\n",
    "    x = Dropout(0.5)(x)\n",
    "    predictions = Dense(1, activation='sigmoid')(x)\n",
    "    model = Model(inputs=base_model.input, outputs=predictions)\n",
    "    return model"
   ]
  },
  {
   "cell_type": "code",
   "execution_count": null,
   "id": "bafce31c",
   "metadata": {},
   "outputs": [
    {
     "name": "stdout",
     "output_type": "stream",
     "text": [
      "WARNING:tensorflow:From /Users/challa/opt/anaconda3/envs/MLPython-Tf/lib/python3.7/site-packages/tensorflow_core/python/ops/resource_variable_ops.py:1630: calling BaseResourceVariable.__init__ (from tensorflow.python.ops.resource_variable_ops) with constraint is deprecated and will be removed in a future version.\n",
      "Instructions for updating:\n",
      "If using Keras pass *_constraint arguments to layers.\n"
     ]
    },
    {
     "name": "stderr",
     "output_type": "stream",
     "text": [
      "ERROR:root:Internal Python error in the inspect module.\n",
      "Below is the traceback from this internal error.\n",
      "\n",
      "ERROR:root:Internal Python error in the inspect module.\n",
      "Below is the traceback from this internal error.\n",
      "\n",
      "ERROR:root:Internal Python error in the inspect module.\n",
      "Below is the traceback from this internal error.\n",
      "\n"
     ]
    },
    {
     "name": "stdout",
     "output_type": "stream",
     "text": [
      "Traceback (most recent call last):\n",
      "  File \"/Users/challa/opt/anaconda3/envs/MLPython-Tf/lib/python3.7/site-packages/IPython/core/interactiveshell.py\", line 3457, in run_code\n",
      "    exec(code_obj, self.user_global_ns, self.user_ns)\n",
      "  File \"/var/folders/_b/mnqbt7xn6_d624_2_w41cfdr0000gn/T/ipykernel_5430/2409032384.py\", line 1, in <module>\n",
      "    resnet_base = ResNet50(weights='imagenet', include_top=False, input_shape=(img_height, img_width, 3))\n",
      "  File \"/Users/challa/opt/anaconda3/envs/MLPython-Tf/lib/python3.7/site-packages/tensorflow_core/python/keras/applications/__init__.py\", line 49, in wrapper\n",
      "    return base_fun(*args, **kwargs)\n",
      "  File \"/Users/challa/opt/anaconda3/envs/MLPython-Tf/lib/python3.7/site-packages/tensorflow_core/python/keras/applications/resnet.py\", line 33, in ResNet50\n",
      "    return resnet.ResNet50(*args, **kwargs)\n",
      "  File \"/Users/challa/opt/anaconda3/envs/MLPython-Tf/lib/python3.7/site-packages/keras_applications/resnet_common.py\", line 435, in ResNet50\n",
      "    **kwargs)\n",
      "  File \"/Users/challa/opt/anaconda3/envs/MLPython-Tf/lib/python3.7/site-packages/keras_applications/resnet_common.py\", line 411, in ResNet\n",
      "    model.load_weights(weights_path)\n",
      "  File \"/Users/challa/opt/anaconda3/envs/MLPython-Tf/lib/python3.7/site-packages/tensorflow_core/python/keras/engine/training.py\", line 182, in load_weights\n",
      "    return super(Model, self).load_weights(filepath, by_name)\n",
      "  File \"/Users/challa/opt/anaconda3/envs/MLPython-Tf/lib/python3.7/site-packages/tensorflow_core/python/keras/engine/network.py\", line 1373, in load_weights\n",
      "    saving.load_weights_from_hdf5_group(f, self.layers)\n",
      "  File \"/Users/challa/opt/anaconda3/envs/MLPython-Tf/lib/python3.7/site-packages/tensorflow_core/python/keras/saving/hdf5_format.py\", line 645, in load_weights_from_hdf5_group\n",
      "    original_keras_version = f.attrs['keras_version'].decode('utf8')\n",
      "AttributeError: 'str' object has no attribute 'decode'\n",
      "\n",
      "During handling of the above exception, another exception occurred:\n",
      "\n",
      "Traceback (most recent call last):\n",
      "  File \"/Users/challa/opt/anaconda3/envs/MLPython-Tf/lib/python3.7/site-packages/IPython/core/interactiveshell.py\", line 2077, in showtraceback\n",
      "    stb = value._render_traceback_()\n",
      "AttributeError: 'AttributeError' object has no attribute '_render_traceback_'\n",
      "\n",
      "During handling of the above exception, another exception occurred:\n",
      "\n",
      "Traceback (most recent call last):\n",
      "  File \"/Users/challa/opt/anaconda3/envs/MLPython-Tf/lib/python3.7/site-packages/IPython/core/ultratb.py\", line 1101, in get_records\n",
      "    return _fixed_getinnerframes(etb, number_of_lines_of_context, tb_offset)\n",
      "  File \"/Users/challa/opt/anaconda3/envs/MLPython-Tf/lib/python3.7/site-packages/IPython/core/ultratb.py\", line 248, in wrapped\n",
      "    return f(*args, **kwargs)\n",
      "  File \"/Users/challa/opt/anaconda3/envs/MLPython-Tf/lib/python3.7/site-packages/IPython/core/ultratb.py\", line 281, in _fixed_getinnerframes\n",
      "    records = fix_frame_records_filenames(inspect.getinnerframes(etb, context))\n",
      "  File \"/Users/challa/opt/anaconda3/envs/MLPython-Tf/lib/python3.7/inspect.py\", line 1502, in getinnerframes\n",
      "    frameinfo = (tb.tb_frame,) + getframeinfo(tb, context)\n",
      "  File \"/Users/challa/opt/anaconda3/envs/MLPython-Tf/lib/python3.7/inspect.py\", line 1460, in getframeinfo\n",
      "    filename = getsourcefile(frame) or getfile(frame)\n",
      "  File \"/Users/challa/opt/anaconda3/envs/MLPython-Tf/lib/python3.7/inspect.py\", line 696, in getsourcefile\n",
      "    if getattr(getmodule(object, filename), '__loader__', None) is not None:\n",
      "  File \"/Users/challa/opt/anaconda3/envs/MLPython-Tf/lib/python3.7/inspect.py\", line 733, in getmodule\n",
      "    if ismodule(module) and hasattr(module, '__file__'):\n",
      "  File \"/Users/challa/opt/anaconda3/envs/MLPython-Tf/lib/python3.7/site-packages/tensorflow/__init__.py\", line 50, in __getattr__\n",
      "    module = self._load()\n",
      "  File \"/Users/challa/opt/anaconda3/envs/MLPython-Tf/lib/python3.7/site-packages/tensorflow/__init__.py\", line 44, in _load\n",
      "    module = _importlib.import_module(self.__name__)\n",
      "  File \"/Users/challa/opt/anaconda3/envs/MLPython-Tf/lib/python3.7/importlib/__init__.py\", line 127, in import_module\n",
      "    return _bootstrap._gcd_import(name[level:], package, level)\n",
      "  File \"<frozen importlib._bootstrap>\", line 1006, in _gcd_import\n",
      "  File \"<frozen importlib._bootstrap>\", line 983, in _find_and_load\n",
      "  File \"<frozen importlib._bootstrap>\", line 967, in _find_and_load_unlocked\n",
      "  File \"<frozen importlib._bootstrap>\", line 677, in _load_unlocked\n",
      "  File \"<frozen importlib._bootstrap_external>\", line 728, in exec_module\n",
      "  File \"<frozen importlib._bootstrap>\", line 219, in _call_with_frames_removed\n",
      "  File \"/Users/challa/opt/anaconda3/envs/MLPython-Tf/lib/python3.7/site-packages/tensorflow_core/contrib/__init__.py\", line 39, in <module>\n",
      "    from tensorflow.contrib import compiler\n",
      "  File \"/Users/challa/opt/anaconda3/envs/MLPython-Tf/lib/python3.7/site-packages/tensorflow_core/contrib/compiler/__init__.py\", line 21, in <module>\n",
      "    from tensorflow.contrib.compiler import jit\n",
      "  File \"/Users/challa/opt/anaconda3/envs/MLPython-Tf/lib/python3.7/site-packages/tensorflow_core/contrib/compiler/__init__.py\", line 22, in <module>\n",
      "    from tensorflow.contrib.compiler import xla\n",
      "  File \"/Users/challa/opt/anaconda3/envs/MLPython-Tf/lib/python3.7/site-packages/tensorflow_core/contrib/compiler/xla.py\", line 22, in <module>\n",
      "    from tensorflow.python.estimator import model_fn as model_fn_lib\n",
      "  File \"/Users/challa/opt/anaconda3/envs/MLPython-Tf/lib/python3.7/site-packages/tensorflow_core/python/estimator/model_fn.py\", line 26, in <module>\n",
      "    from tensorflow_estimator.python.estimator import model_fn\n",
      "  File \"/Users/challa/opt/anaconda3/envs/MLPython-Tf/lib/python3.7/site-packages/tensorflow_estimator/__init__.py\", line 10, in <module>\n",
      "    from tensorflow_estimator._api.v1 import estimator\n",
      "  File \"/Users/challa/opt/anaconda3/envs/MLPython-Tf/lib/python3.7/site-packages/tensorflow_estimator/_api/v1/estimator/__init__.py\", line 10, in <module>\n",
      "    from tensorflow_estimator._api.v1.estimator import experimental\n",
      "  File \"/Users/challa/opt/anaconda3/envs/MLPython-Tf/lib/python3.7/site-packages/tensorflow_estimator/_api/v1/estimator/experimental/__init__.py\", line 10, in <module>\n",
      "    from tensorflow_estimator.python.estimator.canned.dnn import dnn_logit_fn_builder\n",
      "  File \"/Users/challa/opt/anaconda3/envs/MLPython-Tf/lib/python3.7/site-packages/tensorflow_estimator/python/estimator/canned/dnn.py\", line 27, in <module>\n",
      "    from tensorflow_estimator.python.estimator import estimator\n",
      "  File \"/Users/challa/opt/anaconda3/envs/MLPython-Tf/lib/python3.7/site-packages/tensorflow_estimator/python/estimator/estimator.py\", line 36, in <module>\n",
      "    from tensorflow.python.profiler import trace\n",
      "ImportError: cannot import name 'trace' from 'tensorflow.python.profiler' (/Users/challa/opt/anaconda3/envs/MLPython-Tf/lib/python3.7/site-packages/tensorflow_core/python/profiler/__init__.py)\n",
      "Traceback (most recent call last):\n",
      "  File \"/Users/challa/opt/anaconda3/envs/MLPython-Tf/lib/python3.7/site-packages/IPython/core/interactiveshell.py\", line 3457, in run_code\n",
      "    exec(code_obj, self.user_global_ns, self.user_ns)\n",
      "  File \"/var/folders/_b/mnqbt7xn6_d624_2_w41cfdr0000gn/T/ipykernel_5430/2409032384.py\", line 1, in <module>\n",
      "    resnet_base = ResNet50(weights='imagenet', include_top=False, input_shape=(img_height, img_width, 3))\n",
      "  File \"/Users/challa/opt/anaconda3/envs/MLPython-Tf/lib/python3.7/site-packages/tensorflow_core/python/keras/applications/__init__.py\", line 49, in wrapper\n",
      "    return base_fun(*args, **kwargs)\n",
      "  File \"/Users/challa/opt/anaconda3/envs/MLPython-Tf/lib/python3.7/site-packages/tensorflow_core/python/keras/applications/resnet.py\", line 33, in ResNet50\n",
      "    return resnet.ResNet50(*args, **kwargs)\n",
      "  File \"/Users/challa/opt/anaconda3/envs/MLPython-Tf/lib/python3.7/site-packages/keras_applications/resnet_common.py\", line 435, in ResNet50\n",
      "    **kwargs)\n",
      "  File \"/Users/challa/opt/anaconda3/envs/MLPython-Tf/lib/python3.7/site-packages/keras_applications/resnet_common.py\", line 411, in ResNet\n",
      "    model.load_weights(weights_path)\n",
      "  File \"/Users/challa/opt/anaconda3/envs/MLPython-Tf/lib/python3.7/site-packages/tensorflow_core/python/keras/engine/training.py\", line 182, in load_weights\n",
      "    return super(Model, self).load_weights(filepath, by_name)\n",
      "  File \"/Users/challa/opt/anaconda3/envs/MLPython-Tf/lib/python3.7/site-packages/tensorflow_core/python/keras/engine/network.py\", line 1373, in load_weights\n",
      "    saving.load_weights_from_hdf5_group(f, self.layers)\n",
      "  File \"/Users/challa/opt/anaconda3/envs/MLPython-Tf/lib/python3.7/site-packages/tensorflow_core/python/keras/saving/hdf5_format.py\", line 645, in load_weights_from_hdf5_group\n",
      "    original_keras_version = f.attrs['keras_version'].decode('utf8')\n",
      "AttributeError: 'str' object has no attribute 'decode'\n",
      "\n",
      "During handling of the above exception, another exception occurred:\n",
      "\n",
      "Traceback (most recent call last):\n",
      "  File \"/Users/challa/opt/anaconda3/envs/MLPython-Tf/lib/python3.7/site-packages/IPython/core/interactiveshell.py\", line 2077, in showtraceback\n",
      "    stb = value._render_traceback_()\n",
      "AttributeError: 'AttributeError' object has no attribute '_render_traceback_'\n",
      "\n",
      "During handling of the above exception, another exception occurred:\n",
      "\n",
      "Traceback (most recent call last):\n",
      "  File \"/Users/challa/opt/anaconda3/envs/MLPython-Tf/lib/python3.7/site-packages/IPython/core/interactiveshell.py\", line 3377, in run_ast_nodes\n",
      "    if (await self.run_code(code, result,  async_=asy)):\n",
      "  File \"/Users/challa/opt/anaconda3/envs/MLPython-Tf/lib/python3.7/site-packages/IPython/core/interactiveshell.py\", line 3474, in run_code\n",
      "    self.showtraceback(running_compiled_code=True)\n",
      "  File \"/Users/challa/opt/anaconda3/envs/MLPython-Tf/lib/python3.7/site-packages/IPython/core/interactiveshell.py\", line 2080, in showtraceback\n",
      "    value, tb, tb_offset=tb_offset)\n",
      "  File \"/Users/challa/opt/anaconda3/envs/MLPython-Tf/lib/python3.7/site-packages/IPython/core/ultratb.py\", line 1368, in structured_traceback\n",
      "    self, etype, value, tb, tb_offset, number_of_lines_of_context)\n",
      "  File \"/Users/challa/opt/anaconda3/envs/MLPython-Tf/lib/python3.7/site-packages/IPython/core/ultratb.py\", line 1268, in structured_traceback\n",
      "    self, etype, value, tb, tb_offset, number_of_lines_of_context\n",
      "  File \"/Users/challa/opt/anaconda3/envs/MLPython-Tf/lib/python3.7/site-packages/IPython/core/ultratb.py\", line 1125, in structured_traceback\n",
      "    tb_offset)\n",
      "  File \"/Users/challa/opt/anaconda3/envs/MLPython-Tf/lib/python3.7/site-packages/IPython/core/ultratb.py\", line 1082, in format_exception_as_a_whole\n",
      "    last_unique, recursion_repeat = find_recursion(orig_etype, evalue, records)\n",
      "  File \"/Users/challa/opt/anaconda3/envs/MLPython-Tf/lib/python3.7/site-packages/IPython/core/ultratb.py\", line 382, in find_recursion\n",
      "    return len(records), 0\n",
      "TypeError: object of type 'NoneType' has no len()\n",
      "\n",
      "During handling of the above exception, another exception occurred:\n",
      "\n",
      "Traceback (most recent call last):\n",
      "  File \"/Users/challa/opt/anaconda3/envs/MLPython-Tf/lib/python3.7/site-packages/IPython/core/interactiveshell.py\", line 2077, in showtraceback\n",
      "    stb = value._render_traceback_()\n",
      "AttributeError: 'TypeError' object has no attribute '_render_traceback_'\n",
      "\n",
      "During handling of the above exception, another exception occurred:\n",
      "\n",
      "Traceback (most recent call last):\n",
      "  File \"/Users/challa/opt/anaconda3/envs/MLPython-Tf/lib/python3.7/site-packages/IPython/core/ultratb.py\", line 1101, in get_records\n",
      "    return _fixed_getinnerframes(etb, number_of_lines_of_context, tb_offset)\n",
      "  File \"/Users/challa/opt/anaconda3/envs/MLPython-Tf/lib/python3.7/site-packages/IPython/core/ultratb.py\", line 248, in wrapped\n",
      "    return f(*args, **kwargs)\n",
      "  File \"/Users/challa/opt/anaconda3/envs/MLPython-Tf/lib/python3.7/site-packages/IPython/core/ultratb.py\", line 281, in _fixed_getinnerframes\n",
      "    records = fix_frame_records_filenames(inspect.getinnerframes(etb, context))\n",
      "  File \"/Users/challa/opt/anaconda3/envs/MLPython-Tf/lib/python3.7/inspect.py\", line 1502, in getinnerframes\n",
      "    frameinfo = (tb.tb_frame,) + getframeinfo(tb, context)\n",
      "  File \"/Users/challa/opt/anaconda3/envs/MLPython-Tf/lib/python3.7/inspect.py\", line 1460, in getframeinfo\n",
      "    filename = getsourcefile(frame) or getfile(frame)\n",
      "  File \"/Users/challa/opt/anaconda3/envs/MLPython-Tf/lib/python3.7/inspect.py\", line 696, in getsourcefile\n",
      "    if getattr(getmodule(object, filename), '__loader__', None) is not None:\n",
      "  File \"/Users/challa/opt/anaconda3/envs/MLPython-Tf/lib/python3.7/inspect.py\", line 733, in getmodule\n",
      "    if ismodule(module) and hasattr(module, '__file__'):\n",
      "  File \"/Users/challa/opt/anaconda3/envs/MLPython-Tf/lib/python3.7/site-packages/tensorflow/__init__.py\", line 50, in __getattr__\n",
      "    module = self._load()\n",
      "  File \"/Users/challa/opt/anaconda3/envs/MLPython-Tf/lib/python3.7/site-packages/tensorflow/__init__.py\", line 44, in _load\n",
      "    module = _importlib.import_module(self.__name__)\n",
      "  File \"/Users/challa/opt/anaconda3/envs/MLPython-Tf/lib/python3.7/importlib/__init__.py\", line 127, in import_module\n",
      "    return _bootstrap._gcd_import(name[level:], package, level)\n",
      "  File \"<frozen importlib._bootstrap>\", line 1006, in _gcd_import\n",
      "  File \"<frozen importlib._bootstrap>\", line 983, in _find_and_load\n",
      "  File \"<frozen importlib._bootstrap>\", line 965, in _find_and_load_unlocked\n",
      "ModuleNotFoundError: No module named 'tensorflow_core.estimator'\n",
      "Traceback (most recent call last):\n",
      "  File \"/Users/challa/opt/anaconda3/envs/MLPython-Tf/lib/python3.7/site-packages/IPython/core/interactiveshell.py\", line 3457, in run_code\n",
      "    exec(code_obj, self.user_global_ns, self.user_ns)\n",
      "  File \"/var/folders/_b/mnqbt7xn6_d624_2_w41cfdr0000gn/T/ipykernel_5430/2409032384.py\", line 1, in <module>\n",
      "    resnet_base = ResNet50(weights='imagenet', include_top=False, input_shape=(img_height, img_width, 3))\n",
      "  File \"/Users/challa/opt/anaconda3/envs/MLPython-Tf/lib/python3.7/site-packages/tensorflow_core/python/keras/applications/__init__.py\", line 49, in wrapper\n",
      "    return base_fun(*args, **kwargs)\n",
      "  File \"/Users/challa/opt/anaconda3/envs/MLPython-Tf/lib/python3.7/site-packages/tensorflow_core/python/keras/applications/resnet.py\", line 33, in ResNet50\n",
      "    return resnet.ResNet50(*args, **kwargs)\n",
      "  File \"/Users/challa/opt/anaconda3/envs/MLPython-Tf/lib/python3.7/site-packages/keras_applications/resnet_common.py\", line 435, in ResNet50\n",
      "    **kwargs)\n",
      "  File \"/Users/challa/opt/anaconda3/envs/MLPython-Tf/lib/python3.7/site-packages/keras_applications/resnet_common.py\", line 411, in ResNet\n",
      "    model.load_weights(weights_path)\n",
      "  File \"/Users/challa/opt/anaconda3/envs/MLPython-Tf/lib/python3.7/site-packages/tensorflow_core/python/keras/engine/training.py\", line 182, in load_weights\n",
      "    return super(Model, self).load_weights(filepath, by_name)\n",
      "  File \"/Users/challa/opt/anaconda3/envs/MLPython-Tf/lib/python3.7/site-packages/tensorflow_core/python/keras/engine/network.py\", line 1373, in load_weights\n",
      "    saving.load_weights_from_hdf5_group(f, self.layers)\n",
      "  File \"/Users/challa/opt/anaconda3/envs/MLPython-Tf/lib/python3.7/site-packages/tensorflow_core/python/keras/saving/hdf5_format.py\", line 645, in load_weights_from_hdf5_group\n",
      "    original_keras_version = f.attrs['keras_version'].decode('utf8')\n",
      "AttributeError: 'str' object has no attribute 'decode'\n",
      "\n",
      "During handling of the above exception, another exception occurred:\n",
      "\n",
      "Traceback (most recent call last):\n",
      "  File \"/Users/challa/opt/anaconda3/envs/MLPython-Tf/lib/python3.7/site-packages/IPython/core/interactiveshell.py\", line 2077, in showtraceback\n",
      "    stb = value._render_traceback_()\n",
      "AttributeError: 'AttributeError' object has no attribute '_render_traceback_'\n",
      "\n",
      "During handling of the above exception, another exception occurred:\n",
      "\n",
      "Traceback (most recent call last):\n",
      "  File \"/Users/challa/opt/anaconda3/envs/MLPython-Tf/lib/python3.7/site-packages/IPython/core/interactiveshell.py\", line 3377, in run_ast_nodes\n",
      "    if (await self.run_code(code, result,  async_=asy)):\n",
      "  File \"/Users/challa/opt/anaconda3/envs/MLPython-Tf/lib/python3.7/site-packages/IPython/core/interactiveshell.py\", line 3474, in run_code\n",
      "    self.showtraceback(running_compiled_code=True)\n",
      "  File \"/Users/challa/opt/anaconda3/envs/MLPython-Tf/lib/python3.7/site-packages/IPython/core/interactiveshell.py\", line 2080, in showtraceback\n",
      "    value, tb, tb_offset=tb_offset)\n",
      "  File \"/Users/challa/opt/anaconda3/envs/MLPython-Tf/lib/python3.7/site-packages/IPython/core/ultratb.py\", line 1368, in structured_traceback\n",
      "    self, etype, value, tb, tb_offset, number_of_lines_of_context)\n",
      "  File \"/Users/challa/opt/anaconda3/envs/MLPython-Tf/lib/python3.7/site-packages/IPython/core/ultratb.py\", line 1268, in structured_traceback\n",
      "    self, etype, value, tb, tb_offset, number_of_lines_of_context\n",
      "  File \"/Users/challa/opt/anaconda3/envs/MLPython-Tf/lib/python3.7/site-packages/IPython/core/ultratb.py\", line 1125, in structured_traceback\n",
      "    tb_offset)\n",
      "  File \"/Users/challa/opt/anaconda3/envs/MLPython-Tf/lib/python3.7/site-packages/IPython/core/ultratb.py\", line 1082, in format_exception_as_a_whole\n",
      "    last_unique, recursion_repeat = find_recursion(orig_etype, evalue, records)\n",
      "  File \"/Users/challa/opt/anaconda3/envs/MLPython-Tf/lib/python3.7/site-packages/IPython/core/ultratb.py\", line 382, in find_recursion\n",
      "    return len(records), 0\n",
      "TypeError: object of type 'NoneType' has no len()\n",
      "\n",
      "During handling of the above exception, another exception occurred:\n",
      "\n",
      "Traceback (most recent call last):\n",
      "  File \"/Users/challa/opt/anaconda3/envs/MLPython-Tf/lib/python3.7/site-packages/IPython/core/interactiveshell.py\", line 2077, in showtraceback\n",
      "    stb = value._render_traceback_()\n",
      "AttributeError: 'TypeError' object has no attribute '_render_traceback_'\n",
      "\n",
      "During handling of the above exception, another exception occurred:\n",
      "\n",
      "Traceback (most recent call last):\n",
      "  File \"/Users/challa/opt/anaconda3/envs/MLPython-Tf/lib/python3.7/site-packages/IPython/core/interactiveshell.py\", line 2960, in _run_cell\n",
      "    return runner(coro)\n",
      "  File \"/Users/challa/opt/anaconda3/envs/MLPython-Tf/lib/python3.7/site-packages/IPython/core/async_helpers.py\", line 78, in _pseudo_sync_runner\n",
      "    coro.send(None)\n",
      "  File \"/Users/challa/opt/anaconda3/envs/MLPython-Tf/lib/python3.7/site-packages/IPython/core/interactiveshell.py\", line 3186, in run_cell_async\n",
      "    interactivity=interactivity, compiler=compiler, result=result)\n",
      "  File \"/Users/challa/opt/anaconda3/envs/MLPython-Tf/lib/python3.7/site-packages/IPython/core/interactiveshell.py\", line 3396, in run_ast_nodes\n",
      "    self.showtraceback()\n",
      "  File \"/Users/challa/opt/anaconda3/envs/MLPython-Tf/lib/python3.7/site-packages/IPython/core/interactiveshell.py\", line 2080, in showtraceback\n",
      "    value, tb, tb_offset=tb_offset)\n",
      "  File \"/Users/challa/opt/anaconda3/envs/MLPython-Tf/lib/python3.7/site-packages/IPython/core/ultratb.py\", line 1368, in structured_traceback\n",
      "    self, etype, value, tb, tb_offset, number_of_lines_of_context)\n",
      "  File \"/Users/challa/opt/anaconda3/envs/MLPython-Tf/lib/python3.7/site-packages/IPython/core/ultratb.py\", line 1268, in structured_traceback\n",
      "    self, etype, value, tb, tb_offset, number_of_lines_of_context\n",
      "  File \"/Users/challa/opt/anaconda3/envs/MLPython-Tf/lib/python3.7/site-packages/IPython/core/ultratb.py\", line 1143, in structured_traceback\n",
      "    chained_exceptions_tb_offset)\n",
      "  File \"/Users/challa/opt/anaconda3/envs/MLPython-Tf/lib/python3.7/site-packages/IPython/core/ultratb.py\", line 1082, in format_exception_as_a_whole\n",
      "    last_unique, recursion_repeat = find_recursion(orig_etype, evalue, records)\n",
      "  File \"/Users/challa/opt/anaconda3/envs/MLPython-Tf/lib/python3.7/site-packages/IPython/core/ultratb.py\", line 382, in find_recursion\n",
      "    return len(records), 0\n",
      "TypeError: object of type 'NoneType' has no len()\n",
      "\n",
      "During handling of the above exception, another exception occurred:\n",
      "\n",
      "Traceback (most recent call last):\n",
      "  File \"/Users/challa/opt/anaconda3/envs/MLPython-Tf/lib/python3.7/site-packages/IPython/core/interactiveshell.py\", line 2077, in showtraceback\n",
      "    stb = value._render_traceback_()\n",
      "AttributeError: 'TypeError' object has no attribute '_render_traceback_'\n",
      "\n",
      "During handling of the above exception, another exception occurred:\n",
      "\n",
      "Traceback (most recent call last):\n",
      "  File \"/Users/challa/opt/anaconda3/envs/MLPython-Tf/lib/python3.7/site-packages/IPython/core/ultratb.py\", line 1101, in get_records\n",
      "    return _fixed_getinnerframes(etb, number_of_lines_of_context, tb_offset)\n",
      "  File \"/Users/challa/opt/anaconda3/envs/MLPython-Tf/lib/python3.7/site-packages/IPython/core/ultratb.py\", line 248, in wrapped\n",
      "    return f(*args, **kwargs)\n",
      "  File \"/Users/challa/opt/anaconda3/envs/MLPython-Tf/lib/python3.7/site-packages/IPython/core/ultratb.py\", line 281, in _fixed_getinnerframes\n",
      "    records = fix_frame_records_filenames(inspect.getinnerframes(etb, context))\n",
      "  File \"/Users/challa/opt/anaconda3/envs/MLPython-Tf/lib/python3.7/inspect.py\", line 1502, in getinnerframes\n",
      "    frameinfo = (tb.tb_frame,) + getframeinfo(tb, context)\n",
      "  File \"/Users/challa/opt/anaconda3/envs/MLPython-Tf/lib/python3.7/inspect.py\", line 1460, in getframeinfo\n",
      "    filename = getsourcefile(frame) or getfile(frame)\n",
      "  File \"/Users/challa/opt/anaconda3/envs/MLPython-Tf/lib/python3.7/inspect.py\", line 696, in getsourcefile\n",
      "    if getattr(getmodule(object, filename), '__loader__', None) is not None:\n",
      "  File \"/Users/challa/opt/anaconda3/envs/MLPython-Tf/lib/python3.7/inspect.py\", line 733, in getmodule\n",
      "    if ismodule(module) and hasattr(module, '__file__'):\n",
      "  File \"/Users/challa/opt/anaconda3/envs/MLPython-Tf/lib/python3.7/site-packages/tensorflow/__init__.py\", line 50, in __getattr__\n",
      "    module = self._load()\n",
      "  File \"/Users/challa/opt/anaconda3/envs/MLPython-Tf/lib/python3.7/site-packages/tensorflow/__init__.py\", line 44, in _load\n",
      "    module = _importlib.import_module(self.__name__)\n",
      "  File \"/Users/challa/opt/anaconda3/envs/MLPython-Tf/lib/python3.7/importlib/__init__.py\", line 127, in import_module\n",
      "    return _bootstrap._gcd_import(name[level:], package, level)\n",
      "  File \"<frozen importlib._bootstrap>\", line 1006, in _gcd_import\n",
      "  File \"<frozen importlib._bootstrap>\", line 983, in _find_and_load\n",
      "  File \"<frozen importlib._bootstrap>\", line 965, in _find_and_load_unlocked\n",
      "ModuleNotFoundError: No module named 'tensorflow_core.estimator'\n"
     ]
    }
   ],
   "source": [
    "\n",
    "\n",
    "resnet_base = ResNet50(weights='imagenet', include_top=False, input_shape=(img_height, img_width, 3))\n",
    "\n",
    "\n",
    "\n",
    "\n",
    "for layer in resnet_base.layers:\n",
    "    layer.trainable = False\n"
   ]
  },
  {
   "cell_type": "code",
   "execution_count": null,
   "id": "32b6fa23",
   "metadata": {},
   "outputs": [],
   "source": [
    "# Create the models\n",
    "vgg16_model = create_model(vgg16_base)\n",
    "vgg19_model = create_model(vgg19_base)\n",
    "efficientnet_model = create_model(efficientnet_base)\n",
    "resnet_model = create_model(resnet_base)\n",
    "\n",
    "\n",
    "# Compile the models\n",
    "optimizer = Adamax(learning_rate=0.001)\n",
    "\n",
    "vgg16_model.compile(optimizer=optimizer, loss='binary_crossentropy', metrics=['accuracy'])\n",
    "vgg19_model.compile(optimizer=optimizer, loss='binary_crossentropy', metrics=['accuracy'])\n",
    "efficientnet_model.compile(optimizer=optimizer, loss='binary_crossentropy', metrics=['accuracy'])\n",
    "resnet_model.compile(optimizer=optimizer, loss='binary_crossentropy', metrics=['accuracy'])"
   ]
  }
 ],
 "metadata": {
  "kernelspec": {
   "display_name": "Python 3 (ipykernel)",
   "language": "python",
   "name": "python3"
  },
  "language_info": {
   "codemirror_mode": {
    "name": "ipython",
    "version": 3
   },
   "file_extension": ".py",
   "mimetype": "text/x-python",
   "name": "python",
   "nbconvert_exporter": "python",
   "pygments_lexer": "ipython3",
   "version": "3.7.7"
  }
 },
 "nbformat": 4,
 "nbformat_minor": 5
}
